Workbook
Name Daily_Orders: 'Descriptive Analysis'!$H$5:$H$52
Name Daily_revenue: 'Descriptive Analysis'!$I$5:$I$52
Name DailyOrders: 'Descriptive Analysis'!$H$5:$H$52
Name DailyRevenue: 'Descriptive Analysis'!$I$5:$I$52

Sheet Menu Details
A1: DishID | B1: DishName | C1: Category(Breakfast/Lunch/Dinner/Snack) | D1: Classification(Veg/Non-veg/Beverage) | E1: PreparationTime(hr:min) | F1: SellingPrice(Rupees) | G1: Ingredients (Per Serving) | H1: Description | I1: Speed of Preparation
A2: 1 | B2: VadaKulambu | C2: Lunch | D2: Veg | E2: 0.0625 | F2: 90 | G2: Gram dal,Toor dal, Tamarind,Onion,Tomato,Sambar powder,Turmeric powder,Mustard seeds,Curry leaves,Asafoetida,Oil,Salt,Coriander leaves | H2: 250ml with 2 no.s vada | I2: Medium
A3: 2 | B3: VathaKulambu | C3: Lunch | D3: Veg | E3: 0.041666667 | F3: 75 | G3: Gram dal,Toor dal, Tamarind,Onion,Tomato,Sambar powder,Turmeric powder,Mustard seeds,Curry leaves,Asafoetida,Oil,Salt,Coriander leaves | H3: 250ml with 2 no.s vada | I3: Quick | K3: TOTAL DISHES | L3: =COUNTA(_xlfn.UNIQUE(B2:B264)) -> 115
A4: 3 | B4: SemiyaKichadi | C4: Dinner | D4: Veg | E4: 0.0625 | F4: 75 | G4: Vermicelli (semiya),Mixed vegetables (carrot, beans, peas, potato),Onion,Green chillies,Ginger,Cashews,Ghee,Mustard seeds,Urad dal,Chana dal,Curry leaves,Salt | H4: 500 ml with 100 ml of chutney | I4: Medium
A5: 3 | B5: SemiyaKichadi | C5: Breakfast | D5: Veg | E5: 0.0625 | F5: 75 | G5: Vermicelli (semiya),Mixed vegetables (carrot, beans, peas, potato),Onion,Green chillies,Ginger,Cashews,Ghee,Mustard seeds,Urad dal,Chana dal,Curry leaves,Salt | H5: 500 ml with 100 ml of chutney | I5: Medium
A6: 3 | B6: SemiyaKichadi | C6: Snacks | D6: Veg | E6: 0.0625 | F6: 75 | G6: Vermicelli (semiya),Mixed vegetables (carrot, beans, peas, potato),Onion,Green chillies,Ginger,Cashews,Ghee,Mustard seeds,Urad dal,Chana dal,Curry leaves,Salt | H6: 500 ml with 100 ml of chutney | I6: Medium
A7: 4 | B7: Idlywithsambharandchutney | C7: Dinner | D7: Veg | E7: 0.041666667 | F7: 60 | G7: Idli rice,Urad dal,Fenugreek seeds,Salt,Toor dal,Tamarind,Drumstick, carrot, tomato, onion,Sambar powder,Turmeric powder,Mustard seeds,Curry leaves,Asafoetida,Oil,Salt,Coconut,Roasted gram dal,Green chillies,Ginger | H7: 3 no.s idli with 100 ml sambhar and chutney | I7: Quick
A8: 4 | B8: Idlywithsambharandchutney | C8: Breakfast | D8: Veg | E8: 0.083333333 | F8: 60 | G8: Idli rice,Urad dal,Fenugreek seeds,Salt,Toor dal,Tamarind,Drumstick, carrot, tomato, onion,Sambar powder,Turmeric powder,Mustard seeds,Curry leaves,Asafoetida,Oil,Salt,Coconut,Roasted gram dal,Green chillies,Ginger | H8: 3 no.s idli with 100 ml sambhar and chutney | I8: Slow
A9: 5 | B9: VegBiryani | C9: Lunch | D9: Veg | E9: 0.083333333 | F9: 160 | G9: Basmati rice, Mixed vegetables (carrot, beans, potato, cauliflower, peas), Onion, Tomato, Yogurt, Ginger-garlic paste, Green chillies, Mint leaves, Coriander leaves, Biryani masala, Turmeric powder, Red chilli powder, Whole spices (bay leaf, cinnamon, cloves, cardamom), Ghee, Oil, Salt | H9: 750ml veg biryani with seeraga sambha rice wih 100 ml raita | I9: Slow
A10: 5 | B10: VegBiryani | C10: Dinner | D10: Veg | E10: 0.083333333 | F10: 160 | G10: Basmati rice, Mixed vegetables (carrot, beans, potato, cauliflower, peas), Onion, Tomato, Yogurt, Ginger-garlic paste, Green chillies, Mint leaves, Coriander leaves, Biryani masala, Turmeric powder, Red chilli powder, Whole spices (bay leaf, cinnamon, cloves, cardamom), Ghee, Oil, Salt | H10: 750ml veg biryani with seeraga sambha rice wih 100 ml raita | I10: Slow
A11: 6 | B11: PotatoThokku | C11: Dinner | D11: Veg | E11: 0.041666667 | F11: 70 | G11: Potato, Onion, Tomato, Ginger-garlic paste, Green chillies, Red chilli powder, Turmeric powder, Coriander powder, Cumin powder, Curry leaves, Mustard seeds, Oil, Salt, Coriander leaves | H11: 250ml of potato thokku | I11: Quick
A12: 6 | B12: PotatoThokku | C12: Lunch | D12: Veg | E12: 0.041666667 | F12: 70 | G12: Potato, Onion, Tomato, Ginger-garlic paste, Green chillies, Red chilli powder, Turmeric powder, Coriander powder, Cumin powder, Curry leaves, Mustard seeds, Oil, Salt, Coriander leaves | H12: 250ml of potato thokku | I12: Quick
A13: 6 | B13: PotatoThokku | C13: Breakfast | D13: Veg | E13: 0.041666667 | F13: 70 | G13: Potato, Onion, Tomato, Ginger-garlic paste, Green chillies, Red chilli powder, Turmeric powder, Coriander powder, Cumin powder, Curry leaves, Mustard seeds, Oil, Salt, Coriander leaves | H13: 250ml of potato thokku | I13: Quick
A14: 7 | B14: Eggfry | C14: Lunch | D14: Non-veg | E14: 0.041666667 | F14: 60 | G14: Eggs, Onion, Green chillies, Turmeric powder, Red chilli powder, Pepper powder, Curry leaves, Oil, Salt | H14: 3 no.s of egg tawa fry | I14: Quick
A15: 7 | B15: Eggfry | C15: Dinner | D15: Non-veg | E15: 0.041666667 | F15: 60 | G15: Eggs, Onion, Green chillies, Turmeric powder, Red chilli powder, Pepper powder, Curry leaves, Oil, Salt | H15: 3 no.s of egg tawa fry | I15: Quick
... A264: 114 | B264: Pomegranatejuice | C264: Snacks | D264: Beverage | E264: 0.03125 | F264: 70 | G264: Pomegranate, Sugar (optional), Lemon juice (optional), Salt (optional), Ice cubes | H264: 300ml of freshly prepared juice | I264: Quick
A266: MENU STATISTICS
B268: Count according to Category (Breakfast/Lunch/Dinner/Snack) | E268: Pivot table
B269: No.of Breakfast foods | C269: =COUNTIF(Table1[Category(Breakfast/Lunch/Dinner/Snack)],"Breakfast") -> 46
B270: No.of Lunch foods | C270: =COUNTIF(Table1[Category(Breakfast/Lunch/Dinner/Snack)],"Lunch") -> 92 | E270: Row Labels | F270: Average of Selling Price (Rupees)
B271: No.of Snacks foods | C271: =COUNTIF(Table1[Category(Breakfast/Lunch/Dinner/Snack)],"Snacks") -> 24 | E271: Breakfast | F271: 110.95652
B272: No.of Dinner foods | C272: =COUNTIF(Table1[Category(Breakfast/Lunch/Dinner/Snack)],"Dinner") -> 101 | E272: Dinner | F272: 137.92079
E273: Lunch | F273: 147.15217
B274: Count according to Classification (Veg/Non-veg/Beverage) | E274: Snacks | F274: 150.16667
B275: Veg | C275: =COUNTIF(Table1[Classification(Veg/Non-veg/Beverage)],"Veg") -> 147 | E275: Grand Total | F275: 137.55133
B276: Non-veg | C276: =COUNTIF(Table1[Classification(Veg/Non-veg/Beverage)],"Non-veg") -> 105
B277: Beverage | C277: =COUNTIF(Table1[Classification(Veg/Non-veg/Beverage)],"Beverage") -> 11 | E277: Speed | F277: Criteria
E278: Quick | F278: <=1hr
B279: Average price by category | C279: Rupees | E279: Medium | F279: >1hr and <=1hr 30min
B280: Breakfast | C280: =GETPIVOTDATA("Selling Price (Rupees)",$E$270,"Category (Breakfast/Lunch/Dinner/Snack)","Breakfast") -> 110.95652 | E280: Slow | F280: >1hr 30min and <=3hr
B281: Lunch | C281: =GETPIVOTDATA("Selling Price (Rupees)",$E$270,"Category (Breakfast/Lunch/Dinner/Snack)","Lunch") -> 147.15217
B282: Snacks | C282: =GETPIVOTDATA("Selling Price (Rupees)",$E$270,"Category (Breakfast/Lunch/Dinner/Snack)","Snacks") -> 150.16667
B283: Dinner | C283: =GETPIVOTDATA("Selling Price (Rupees)",$E$270,"Category (Breakfast/Lunch/Dinner/Snack)","Dinner") -> 137.92079
B285: Highest Priced Dish | C285: Non veg family combo 2, Chicken Family Combo | D285: =MAX(Table1[SellingPrice(Rupees)]) -> 699
B286: Lowest Priced Dish | C286: Egg fry, Idly with sambhar and chutney, Paruppu thakkali kadayal, Double Omelette | D286: =MIN(Table1[SellingPrice(Rupees)]) -> 60
B288: Average prep time by category | C288: hr : min
B289: Breakfast | C289: =GETPIVOTDATA("Preparation Time (hr:min)",$E$290,"Category (Breakfast/Lunch/Dinner/Snack)","Breakfast") -> 0.061443237
B290: Lunch | C290: =GETPIVOTDATA("Preparation Time (hr:min)",$E$290,"Category (Breakfast/Lunch/Dinner/Snack)","Lunch") -> 0.063896437 | E290: Row Labels | F290: Average of Preparation Time (hr:min)
B291: Snacks | C291: =GETPIVOTDATA("Preparation Time (hr:min)",$E$290,"Category (Breakfast/Lunch/Dinner/Snack)","Snacks") -> 0.058159722 | E291: Breakfast | F291: 0.061443237
B292: Dinner | C292: =GETPIVOTDATA("Preparation Time (hr:min)",$E$290,"Category (Breakfast/Lunch/Dinner/Snack)","Dinner") -> 0.061949945 | E292: Dinner | F292: 0.061949945
...

Sheet Order Data  
A1: ORDER ID | B1: DATE | C1: DAY | D1: CATEGORY(BREAKFAST/LUNCH/SNACKS/DINNER) | E1: TYPE(SUBSCRIPTION/REGULAR) | F1: DISH NAME | G1: QUANTITY | H1: ORDER VALUE | I1: CLASSIFICATION(Veg/Non-veg/Beverage) | J1: Date2 | K1: TYPE_FIXED
A2: CS-250331-0219 | B2: 45748 | C2: Tuesday | D2: Lunch | E2: SUBSCRIPTION | F2: Rice(750ml), Sambar(250ml),Vendakkai fry(100ml),keerai poriyal(100ml),Mor (100ml),Rasam(100ml), Appalam | G2: 1 | H2: 129 | I2: Veg | J2: 45748 | K2: =IF(E2<>"", E2, K1) -> SUBSCRIPTION
A3: CS-250331-0242 | B3: 45748 | C3: Tuesday | D3: Dinner | E3: SUBSCRIPTION | F3: Egg kothu chappathi(500ml) with gravy (100ml) | G3: 1 | H3: 117 | I3: Veg | J3: 45748 | K3: =IF(E3<>"", E3, K2) -> SUBSCRIPTION | L3: METRIC | M3: VALUE
A4: CS-250331-0232 | B4: 45748 | C4: Tuesday | D4: Dinner | E4: SUBSCRIPTION | F4: Ragi idiyapam(4no.s) with white kurma(250ml) | G4: 1 | H4: 99 | I4: Veg | J4: 45748 | K4: =IF(E4<>"", E4, K3) -> SUBSCRIPTION | L4: Total Orders | M4: =COUNTA(A2:A881) -> 567
A5: CS-250331-0246 | B5: 45748 | C5: Tuesday | D5: Dinner | E5: SUBSCRIPTION | F5: Steamed rice (500ml), Dhal (250ml), Chicken 65 (100ml), Boiled egg (1 nos), Rasam (100ml) | G5: 1 | H5: 129 | I5: Non-veg | J5: 45748 | K5: =IF(E5<>"", E5, K4) -> SUBSCRIPTION | L5: Operating Days | M5: =COUNTA(_xlfn.UNIQUE(B2:B881)) -> 49
A6: CS-250331-0236 | B6: 45748 | C6: Tuesday | D6: Breakfast | E6: SUBSCRIPTION | F6: Chapathi (4 nos) with Veg gravy (250ml) | G6: 2 | H6: =2*99 -> 198 | I6: Veg | J6: 45748 | K6: =IF(E6<>"", E6, K5) -> SUBSCRIPTION | L6: Average Order per day | M6: =M4/M5 -> 11.571429
A7: CS-250331-0257 | B7: 45748 | C7: Tuesday | D7: Breakfast | E7: SUBSCRIPTION | F7: Chapathi (4 nos) with Veg gravy (250ml) | G7: 1 | H7: 99 | I7: Veg | J7: 45748 | K7: =IF(E7<>"", E7, K6) -> SUBSCRIPTION | L7: Minimum orders (single day) | M7: =MIN(O18:O66) -> 1
A8: CS-250401-0026 | B8: 45748 | C8: Tuesday | D8: Lunch | E8: REGULAR | F8: Sambar | G8: 1 | H8: 65 | I8: Veg | J8: 45748 | K8: =IF(E8<>"", E8, K7) -> REGULAR | L8: Maximum orders single day | M8: =MAX(O18:O66) -> 567
A9: CS-250401-0074 | B9: 45748 | C9: Tuesday | D9: Lunch | E9: REGULAR | F9: Vegetable poriyal, Chicken thokku, Sambar | G9: 1 | H9: 290 | I9: Veg | J9: 45748 | K9: =IF(E9<>"", E9, K8) -> REGULAR | L9: Total revenue | M9: =SUM(H2:H881) -> 117986
A10: CS-250401-0087 | B10: 45748 | C10: Tuesday | D10: Lunch | E10: REGULAR | F10: Rice with sambar and poriyal | G10: 1 | H10: 95 | I10: Veg | J10: 45748 | K10: =IF(E10<>"", E10, K9) -> REGULAR | L10: Average order value | M10: =M9/M4 -> 208.08818
A11: CS-250401-0136 | B11: 45748 | C11: Tuesday | D11: Lunch | E11: REGULAR | F11: Egg kurma | G11: 1 | H11: 240 | I11: Veg | J11: 45748 | K11: =IF(E11<>"", E11, K10) -> REGULAR | L11: Most Ordered Dish (Subscription) | M11: Ragi idiyapam(4no.s) with white kurma(250ml)
F12: Vegetable poriyal | G12: 1 | I12: Veg | J12: =J11 -> 45748 | K12: =IF(E12<>"", E12, K11) -> REGULAR | L12: Most Ordered Dish (Regular) | M12: Keerai paruppu kadayal
F13: Rice with sambar and poriyal | G13: 1 | I13: Veg | J13: =J12 -> 45748 | K13: =IF(E13<>"", E13, K12) -> REGULAR | L13: Most Ordered Dish (Regular) | M13: Keerai paruppu kadayal
A14: CS-250401-0142 | B14: 45748 | C14: Tuesday | D14: Lunch | E14: REGULAR | F14: Rice with sambar and poriyal | G14: 1 | H14: 95 | I14: Veg | J14: 45748 | K14: =IF(E14<>"", E14, K13) -> REGULAR | L14: Most Ordered Dish (Regular) | M14: Keerai paruppu kadayal
A15: CS-250401-0174 | B15: 45749 | C15: Wednesday | D15: Breakfast | E15: SUBSCRIPTION | F15: Ragi Chapathi(4no.s) with mushroom gravy(250ml) | G15: 1 | H15: 117 | I15: Veg | J15: 45749 | K15: =IF(E15<>"", E15, K14) -> SUBSCRIPTION
A16: CS-250401-0177 | B16: 45749 | C16: Wednesday | D16: Dinner | E16: SUBSCRIPTION | F16: Pesarattu dosa(3no.s) with kaara chutney(250ml), Omelette (1 nos) | G16: 1 | H16: 99 | I16: Non-veg | J16: 45749 | K16: =IF(E16<>"", E16, K15) -> SUBSCRIPTION | N16: GRAPH 1: ORDER TREND | S16: `
A17: CS-250401-0183 | B17: 45749 | C17: Wednesday | D17: Lunch | E17: SUBSCRIPTION | F17: Rice(750ml), Potato fry(100ml),kathirikkai kootu(100ml),Mor kuzhambu(250ml),Mor(100ml),Rasam(100ml), Appalam | G17: 1 | H17: 129 | I17: Veg | J17: 45749 | K17: =IF(E17<>"", E17, K16) -> SUBSCRIPTION | N17: Row Labels | O17: Count of ORDER ID
A18: CS-250401-0189 | B18: 45749 | C18: Wednesday | D18: Dinner | E18: SUBSCRIPTION | F18: Idly (4 pcs) with Fish kulambu (250ml) | G18: 1 | H18: 112 | I18: Non-veg | J18: 45749 | K18: =IF(E18<>"", E18, K17) -> SUBSCRIPTION | N18: 45748 | O18: 11
A19: CS-250401-0193 | B19: 45749 | C19: Wednesday | D19: Lunch | E19: SUBSCRIPTION | F19: Steamed rice (500ml), Fish gravy (250ml) with pcs, Rasam (100ml) | G19: 1 | H19: 179 | I19: Non-veg | J19: 45749 | K19: =IF(E19<>"", E19, K18) -> SUBSCRIPTION | N19: 45749 | O19: 11
A20: CS-250401-0192 | B20: 45749 | C20: Wednesday | D20: Breakfast | E20: SUBSCRIPTION | F20: Uthappam (3 nos) with puthina chutney (250ml) | G20: 2 | H20: =2*79 -> 158 | I20: Veg | J20: 45749 | K20: =IF(E20<>"", E20, K19) -> SUBSCRIPTION | N20: 45750 | O20: 18
A21: CS-250401-0208 | B21: 45749 | C21: Wednesday | D21: Lunch | E21: SUBSCRIPTION | F21: Steamed rice (500ml), Fish gravy (250ml) with pcs, Rasam (100ml) | G21: 1 | H21: 179 | I21: Non-veg | J21: 45749 | K21: =IF(E21<>"", E21, K20) -> SUBSCRIPTION | N21: 45751 | O21: 18
A22: CS-250401-0206 | B22: 45749 | C22: Wednesday | D22: Breakfast | E22: SUBSCRIPTION | F22: Poori(4no.s) with chicken kuzhambu (250ml) | G22: 1 | H22: 129 | I22: Non-veg | J22: 45749 | K22: =IF(E22<>"", E22, K21) -> SUBSCRIPTION | N22: 45752 | O22: 17
A23: CS-250401-0201 | B23: 45749 | C23: Wednesday | D23: Dinner | E23: SUBSCRIPTION | F23: Pesarattu dosa(3no.s) with kaara chutney(250ml), Omelette (1 nos) | G23: 1 | H23: 99 | I23: Non-veg | J23: 45749 | K23: =IF(E23<>"", E23, K22) -> SUBSCRIPTION | N23: 45753 | O23: 20
A24: CS-250401-0210 | B24: 45749 | C24: Wednesday | D24: Lunch | E24: SUBSCRIPTION | F24: Steamed rice (500ml), Fish gravy (250ml) with pcs, Rasam (100ml) | G24: 1 | H24: 179 | I24: Non-veg | J24: 45749 | K24: =IF(E24<>"", E24, K23) -> SUBSCRIPTION | N24: 45754 | O24: 16
A25: CS-250402-0025 | B25: 45749 | C25: Wednesday | D25: Lunch | E25: REGULAR | F25: Organic Karuppu kavuni kanji | G25: 2 | H25: 280 | I25: Veg | J25: 45749 | K25: =IF(E25<>"", E25, K24) -> REGULAR | N25: 45755 | O25: 21
A26: CS-250402-0208 | B26: 45750 | C26: Thursday | D26: Lunch | E26: SUBSCRIPTION | F26: Rice(750ml), payaru kulambu(250ml), cabbage poriyal(100ml), pudalangai kootu (100ml), rasam(100ml), mor(100ml), appalam | G26: 1 | H26: 129 | I26: Veg | J26: 45750 | K26: =IF(E26<>"", E26, K25) -> SUBSCRIPTION | N26: 45756 | O26: 19
A27: CS-250402-0219 | B27: 45750 | C27: Thursday | D27: Dinner | E27: SUBSCRIPTION | F27: Uluthan kali (500ml) with jaggery | G27: 1 | H27: 117 | I27: Veg | J27: 45750 | K27: =IF(E27<>"", E27, K26) -> SUBSCRIPTION | N27: 45757 | O27: 15
A28: CS-250402-0228 | B28: 45750 | C28: Thursday | D28: Breakfast | E28: SUBSCRIPTION | F28: Wheat samba upma(500ml) with coconut chutney(100ml) | G28: 1 | H28: 79 | I28: Veg | J28: 45750 | K28: =IF(E28<>"", E28, K27) -> SUBSCRIPTION | N28: 45758 | O28: 9
A29: CS-250402-0226 | B29: 45750 | C29: Thursday | D29: Lunch | E29: SUBSCRIPTION | F29: Lemon rice (500ml) with egg pepper fry (2no.s) | G29: 1 | H29: 99 | I29: Non-veg | J29: 45750 | K29: =IF(E29<>"", E29, K28) -> SUBSCRIPTION | N29: 45759 | O29: 12
A30: CS-250402-0239 | B30: 45750 | C30: Thursday | D30: Breakfast | E30: SUBSCRIPTION | F30: Rava bath (500ml) with coconut chutney(100ml) | G30: 2 | H30: =2*79 -> 158 | I30: Veg | J30: 45750 | K30: =IF(E30<>"", E30, K29) -> SUBSCRIPTION | N30: 45760 | O30: 13 | V30: GRAPH 5: Revenue Category-wise Distribution
A31: CS-250402-0238 | B31: 45750 | C31: Thursday | D31: Dinner | E31: SUBSCRIPTION | F31: Chicken fried rice (500ml) with sauce | G31: 1 | H31: 149 | I31: Non-veg | J31: 45750 | K31: =IF(E31<>"", E31, K30) -> SUBSCRIPTION | N31: 45761 | O31: 8
A32: CS-250402-0231 | B32: 45750 | C32: Thursday | D32: Lunch | E32: SUBSCRIPTION | F32: Lemon rice (500ml) with egg pepper fry (2no.s) | G32: 1 | H32: 99 | I32: Non-veg | J32: 45750 | K32: =IF(E32<>"", E32, K31) -> SUBSCRIPTION | N32: 45762 | O32: 13
A33: CS-250402-0223 | B33: 45750 | C33: Thursday | D33: Dinner | E33: SUBSCRIPTION | F33: Chicken fried rice (500ml) with sauce | G33: 1 | H33: 149 | I33: Non-veg | J33: 45750 | K33: =IF(E33<>"", E33, K32) -> SUBSCRIPTION | N33: 45763 | O33: 15
A34: CS-250402-0230 | B34: 45750 | C34: Thursday | D34: Lunch | E34: SUBSCRIPTION | F34: Rice(750ml), tomato curry(250ml), vazhakkai varuval(200ml), rasam(100ml) mor (100ml), appalam, pickle | G34: 1 | H34: 129 | I34: Veg | J34: 45750 | K34: =IF(E34<>"", E34, K33) -> SUBSCRIPTION | N34: 45764 | O34: 13
A35: CS-250402-0233 | B35: 45750 | C35: Thursday | D35: Breakfast | E35: SUBSCRIPTION | F35: Egg dosa (1 no.s), Plain dosa (2 pcs) with sambar (250ml) qnd chutney (100ml) | G35: 1 | H35: 117 | I35: Non-veg | J35: 45750 | K35: =IF(E35<>"", E35, K34) -> SUBSCRIPTION | N35: 45765 | O35: 16
A36: CS-250402-0241 | B36: 45750 | C36: Thursday | D36: Lunch | E36: SUBSCRIPTION | F36: Steamed rice(500ml), veg gravy(250ml),chicken 65(2500ml), poriyal(100ml), curd(100ml) | G36: 1 | H36: 129 | I36: Non-veg | J36: 45750 | K36: =IF(E36<>"", E36, K35) -> SUBSCRIPTION | N36: 45766 | O36: 16
A37: CS-250403-0053 | B37: 45750 | C37: Thursday | D37: Lunch | E37: REGULAR | F37: Keerai kootu | G37: 2 | H37: 160 | I37: Veg | J37: 45750 | K37: =IF(E37<>"", E37, K36) -> REGULAR | N37: 45767 | O37: 14
A38: CS-250403-0054 | B38: 45750 | C38: Thursday | D38: Lunch | E38: REGULAR | F38: Paruppu thakkali kadayal | G38: 1 | H38: 190 | I38: Veg | J38: 45750 | K38: =IF(E38<>"", E38, K37) -> REGULAR | N38: 45768 | O38: 5
F39: Vegetable poriyal | G39: 1 | I39: Veg | J39: =J38 -> 45750 | K39: =IF(E39<>"", E39, K38) -> REGULAR | N39: 45769 | O39: 10
F40: Vegetable kootu | G40: 1 | I40: Veg | J40: =J39 -> 45750 | K40: =IF(E40<>"", E40, K39) -> REGULAR | N40: 45770 | O40: 12
...

Sheet Demand Forecasting
A1: Date | B1: Daily Orders | C1: 7-Day Moving Average | D1: Exponential Smoothing | E1: MAPE %
A2: 45748 | B2: 11 | D2: =B2 -> 11 | E2: 0
A3: 45749 | B3: 11 | D3: =0.3*B2+0.7*D2 -> 11 | E3: =ABS(B3-D2)/B3*100 -> 0
A4: 45750 | B4: 18 | D4: =0.3*B3+0.7*D3 -> 11 | E4: =ABS(B4-D3)/B4*100 -> 38.888889
A5: 45751 | B5: 18 | D5: =0.3*B4+0.7*D4 -> 13.1 | E5: =ABS(B5-D4)/B5*100 -> 38.888889
A6: 45752 | B6: 17 | D6: =0.3*B5+0.7*D5 -> 14.57 | E6: =ABS(B6-D5)/B6*100 -> 22.941176
A7: 45753 | B7: 20 | D7: =0.3*B6+0.7*D6 -> 15.299 | E7: =ABS(B7-D6)/B7*100 -> 27.15
A8: 45754 | B8: 16 | D8: =0.3*B7+0.7*D7 -> 16.7093 | E8: =ABS(B8-D7)/B8*100 -> 4.38125
A9: 45755 | B9: 21 | C9: =AVERAGE(B2:B8) -> 15.857143 | D9: =0.3*B8+0.7*D8 -> 16.49651 | E9: =ABS(B9-D8)/B9*100 -> 20.431905
A10: 45756 | B10: 19 | C10: =AVERAGE(B3:B9) -> 17.285714 | D10: =0.3*B9+0.7*D9 -> 17.847557 | E10: =ABS(B10-D9)/B10*100 -> 13.176263
A11: 45757 | B11: 15 | C11: =AVERAGE(B4:B10) -> 18.428571 | D11: =0.3*B10+0.7*D10 -> 18.19329 | E11: =ABS(B11-D10)/B11*100 -> 18.983713
A12: 45758 | B12: 9 | C12: =AVERAGE(B5:B11) -> 18 | D12: =0.3*B11+0.7*D11 -> 17.235303 | E12: =ABS(B12-D11)/B12*100 -> 102.14767
A13: 45759 | B13: 12 | C13: =AVERAGE(B6:B12) -> 16.714286 | D13: =0.3*B12+0.7*D12 -> 14.764712 | E13: =ABS(B13-D12)/B13*100 -> 43.627524
A14: 45760 | B14: 13 | C14: =AVERAGE(B7:B13) -> 16 | D14: =0.3*B13+0.7*D13 -> 13.935298 | E14: =ABS(B14-D13)/B14*100 -> 13.574708
A15: 45761 | B15: 8 | C15: =AVERAGE(B8:B14) -> 15 | D15: =0.3*B14+0.7*D14 -> 13.654709 | E15: =ABS(B15-D14)/B15*100 -> 74.19123
A16: 45762 | B16: 13 | C16: =AVERAGE(B9:B15) -> 13.857143 | D16: =0.3*B15+0.7*D15 -> 11.958296 | E16: =ABS(B16-D15)/B16*100 -> 5.0362223
A17: 45763 | B17: 15 | C17: =AVERAGE(B10:B16) -> 12.714286 | D17: =0.3*B16+0.7*D16 -> 12.270807 | E17: =ABS(B17-D16)/B17*100 -> 20.278025
A18: 45764 | B18: 13 | C18: =AVERAGE(B11:B17) -> 12.142857 | D18: =0.3*B17+0.7*D17 -> 13.089565 | E18: =ABS(B18-D17)/B18*100 -> 5.6091741
A19: 45765 | B19: 16 | C19: =AVERAGE(B12:B18) -> 11.857143 | D19: =0.3*B18+0.7*D18 -> 13.062696 | E19: =ABS(B19-D18)/B19*100 -> 18.190218
A20: 45766 | B20: 16 | C20: =AVERAGE(B13:B19) -> 12.857143 | D20: =0.3*B19+0.7*D19 -> 13.943887 | E20: =ABS(B20-D19)/B20*100 -> 18.358152
... A49: 45803 | B49: 1 | C49: =AVERAGE(B42:B48) -> 11.142857 | D49: =0.3*B48+0.7*D48 -> 7.4052223 | E49: =ABS(B49-D48)/B49*100 -> 915.03176

Sheet ABC Classification
A1: Ingredient | B1: Local Cost (per kg/unit) | C1: Est. Monthly Usage | D1: (Units) | E1: Annual Usage | F1: Annual Value (₹) | G1: Cumulative % | H1: Class
A2: White rice | B2: 55 | C2: 50 | D2: kg | E2: =C2*12 -> 600 | F2: =B2*E2 -> 33000 | G2: =F2/SUM($F$2:$F$17)*100 -> 15.786452 | H2: =IF(G2<=70,"A",IF(G2<=90,"B","C")) -> A
A3: Toor dal | B3: 180 | C3: 15 | D3: kg | E3: =C3*12 -> 180 | F3: =B3*E3 -> 32400 | G3: =G2+F3/SUM($F$2:$F$17)*100 -> 31.285878 | H3: =IF(G3<=70,"A",IF(G3<=90,"B","C")) -> A
A4: Chicken | B4: 200 | C4: 12 | D4: kg | E4: =C4*12 -> 144 | F4: =B4*E4 -> 28800 | G4: =G3+F4/SUM($F$2:$F$17)*100 -> 45.063146 | H4: =IF(G4<=70,"A",IF(G4<=90,"B","C")) -> A
A5: Ghee | B5: 650 | C5: 2 | D5: L | E5: =C5*12 -> 24 | F5: =B5*E5 -> 15600 | G5: =G4+F5/SUM($F$2:$F$17)*100 -> 52.525832 | H5: =IF(G5<=70,"A",IF(G5<=90,"B","C")) -> A
A6: Cooking oil | B6: 150 | C6: 8 | D6: L | E6: =C6*12 -> 96 | F6: =B6*E6 -> 14400 | G6: =G5+F6/SUM($F$2:$F$17)*100 -> 59.414466 | H6: =IF(G6<=70,"A",IF(G6<=90,"B","C")) -> A
A7: Basmati rice | B7: 115 | C7: 8 | D7: kg | E7: =C7*12 -> 96 | F7: =B7*E7 -> 11040 | G7: =G6+F7/SUM($F$2:$F$17)*100 -> 64.695752 | H7: =IF(G7<=70,"A",IF(G7<=90,"B","C")) -> A
A8: Coconut | B8: 50 | C8: 16 | D8: pcs | E8: =C8*12 -> 192 | F8: =B8*E8 -> 9600 | G8: =G7+F8/SUM($F$2:$F$17)*100 -> 69.288175 | H8: =IF(G8<=70,"A",IF(G8<=90,"B","C")) -> A
A9: Curd | B9: 80 | C9: 10 | D9: L | E9: =C9*12 -> 120 | F9: =B9*E9 -> 9600 | G9: =G8+F9/SUM($F$2:$F$17)*100 -> 73.880597 | H9: =IF(G9<=70,"A",IF(G9<=90,"B","C")) -> B
A10: Tamarind | B10: 400 | C10: 2 | D10: kg | E10: =C10*12 -> 24 | F10: =B10*E10 -> 9600 | G10: =G9+F10/SUM($F$2:$F$17)*100 -> 78.47302 | H10: =IF(G10<=70,"A",IF(G10<=90,"B","C")) -> B
A11: Cashews | B11: 750 | C11: 1 | D11: kg | E11: =C11*12 -> 12 | F11: =B11*E11 -> 9000 | G11: =G10+F11/SUM($F$2:$F$17)*100 -> 82.778416 | H11: =IF(G11<=70,"A",IF(G11<=90,"B","C")) -> B
A12: Eggs | B12: 6 | C12: 120 | D12: pcs | E12: =C12*12 -> 1440 | F12: =B12*E12 -> 8640 | G12: =G11+F12/SUM($F$2:$F$17)*100 -> 86.911596 | H12: =IF(G12<=70,"A",IF(G12<=90,"B","C")) -> B
A13: Onion | B13: 35 | C13: 20 | D13: kg | E13: =C13*12 -> 240 | F13: =B13*E13 -> 8400 | G13: =G12+F13/SUM($F$2:$F$17)*100 -> 90.929966 | H13: =IF(G13<=70,"A",IF(G13<=90,"B","C")) -> C
A14: Tomato | B14: 25 | C14: 20 | D14: kg | E14: =C14*12 -> 240 | F14: =B14*E14 -> 6000 | G14: =G13+F14/SUM($F$2:$F$17)*100 -> 93.80023 | H14: =IF(G14<=70,"A",IF(G14<=90,"B","C")) -> C
... A17: Sambar powder | B17: 45 | C17: 4 | D17: packs | E17: =C17*12 -> 48 | F17: =B17*E17 -> 2160 | G17: =G16+F17/SUM($F$2:$F$17)*100 -> 100 | H17: =IF(G17<=70,"A",IF(G17<=90,"B","C")) -> C

Sheet EOQ and ROP
A1: Ingredient | B1: Avg Daily Demand | C1: (Units) | D1: Std Dev | E1: Lead Time (days) | F1: Annual Demand | G1: Order Cost (₹) | H1: Holding Cost (₹/unit/yr) | I1: EOQ | J1: Safety Stock | K1: ROP
A2: Toor dal | B2: 0.5 | C2: kg | D2: 0.2 | E2: 2 | F2: =B2*365 -> 182.5 | G2: 50 | H2: 18 | I2: =SQRT((2*F2*G2)/H2) -> 31.841622 | J2: =1.645*D2*SQRT(E2) -> 0.46527626 | K2: =B2*E2+J2 -> 1.4652763
A3: White rice | B3: 2 | C3: kg | D3: 0.5 | E3: 2 | F3: =B3*365 -> 730 | G3: 50 | H3: 5.5 | I3: =SQRT((2*F3*G3)/H3) -> 115.20732 | J3: =1.645*D3*SQRT(E3) -> 1.1631907 | K3: =B3*E3+J3 -> 5.1631907
A4: Chicken | B4: 0.4 | C4: kg | D4: 0.3 | E4: 1 | F4: =B4*365 -> 146 | G4: 50 | H4: 20 | I4: =SQRT((2*F4*G4)/H4) -> 27.018512 | J4: =1.645*D4*SQRT(E4) -> 0.4935 | K4: =B4*E4+J4 -> 0.8935
A5: Onion | B5: 1.5 | C5: kg | D5: 0.2 | E5: 2 | F5: =B5*365 -> 547.5 | G5: 30 | H5: 3.5 | I5: =SQRT((2*F5*G5)/H5) -> 96.879896 | J5: =1.645*D5*SQRT(E5) -> 0.46527626 | K5: =B5*E5+J5 -> 3.4652763
A6: Cooking oil | B6: 0.3 | C6: L | D6: 0.1 | E6: 3 | F6: =B6*365 -> 109.5 | G6: 50 | H6: 15 | I6: =SQRT((2*F6*G6)/H6) -> 27.018512 | J6: =1.645*D6*SQRT(E6) -> 0.28492236 | K6: =B6*E6+J6 -> 1.1849224
A7: Eggs | B7: 4 | C7: pcs | D7: 2 | E7: 1 | F7: =B7*365 -> 1460 | G7: 30 | H7: 0.6 | I7: =SQRT((2*F7*G7)/H7) -> 382.09946 | J7: =1.645*D7*SQRT(E7) -> 3.29 | K7: =B7*E7+J7 -> 7.29
A8: Ghee | B8: 0.07 | C8: L | D8: 0.03 | E8: 3 | F8: =B8*365 -> 25.55 | G8: 50 | H8: 65 | I8: =SQRT((2*F8*G8)/H8) -> 6.2695847 | J8: =1.645*D8*SQRT(E8) -> 0.085476707 | K8: =B8*E8+J8 -> 0.29547671

Sheet Contribution Margin
A1: Dish Name | B1: Selling Price (₹) | C1: Ingredient Cost (₹) | D1: Platform Fee (₹) | E1: Total Variable Cost | F1: CM (₹) | G1: CM % | H1: Category
A2: Keerai paruppu kadayal | B2: 120 | C2: 33.77 | D2: =0.3*B2 -> 36 | E2: =C2+D2 -> 69.77 | F2: =B2-E2 -> 50.23 | G2: =F2/B2*100 -> 41.858333 | H2: Star
A3: Chicken Biryani | B3: 190 | C3: 77.56 | D3: =0.3*B3 -> 57 | E3: =C3+D3 -> 134.56 | F3: =B3-E3 -> 55.44 | G3: =F3/B3*100 -> 29.178947 | H3: Plowhorse
A4: Vegetable poriyal | B4: 65 | C4: 40.4 | D4: =0.3*B4 -> 19.5 | E4: =C4+D4 -> 59.9 | F4: =B4-E4 -> 5.1 | G4: =F4/B4*100 -> 7.8461538 | H4: Dog
A5: Chicken thokku | B5: 160 | C5: 38.72 | D5: =0.3*B5 -> 48 | E5: =C5+D5 -> 86.72 | F5: =B5-E5 -> 73.28 | G5: =F5/B5*100 -> 45.8 | H5: Star
A6: White rice | B6: 80 | C6: 16.5 | D6: =0.3*B6 -> 24 | E6: =C6+D6 -> 40.5 | F6: =B6-E6 -> 39.5 | G6: =F6/B6*100 -> 49.375 | H6: Star
A7: Chicken 65 | B7: 150 | C7: 49.67 | D7: =0.3*B7 -> 45 | E7: =C7+D7 -> 94.67 | F7: =B7-E7 -> 55.33 | G7: =F7/B7*100 -> 36.886667 | H7: Star
A8: Rasam | B8: 65 | C8: 20.95 | D8: =0.3*B8 -> 19.5 | E8: =C8+D8 -> 40.45 | F8: =B8-E8 -> 24.55 | G8: =F8/B8*100 -> 37.769231 | H8: Puzzle
A9: Keerai kootu | B9: 80 | C9: 38.85 | D9: =0.3*B9 -> 24 | E9: =C9+D9 -> 62.85 | F9: =B9-E9 -> 17.15 | G9: =F9/B9*100 -> 21.4375 | H9: Dog
A10: Vazhakkai varuval | B10: 80 | C10: 29.77 | D10: =0.3*B10 -> 24 | E10: =C10+D10 -> 53.77 | F10: =B10-E10 -> 26.23 | G10: =F10/B10*100 -> 32.7875 | H10: Dog
A11: Vendakkai poriyal | B11: 70 | C11: 15.43 | D11: =0.3*B11 -> 21 | E11: =C11+D11 -> 36.43 | F11: =B11-E11 -> 33.57 | G11: =F11/B11*100 -> 47.957143 | H11: Puzzle
A12: Ragi idiyapam(4no.s) with white kurma(250ml) | B12: 99 | C12: 38.14 | D12: =0.3*B12 -> 29.7 | E12: =C12+D12 -> 67.84 | F12: =B12-E12 -> 31.16 | G12: =F12/B12*100 -> 31.474747 | H12: Star
A13: Steamed rice (500ml), Fish gravy (250ml) with pcs, Rasam (100ml) | B13: 179 | C13: 74.63 | D13: =0.3*B13 -> 53.7 | E13: =C13+D13 -> 128.33 | F13: =B13-E13 -> 50.67 | G13: =F13/B13*100 -> 28.307263 | H13: Star
... A21: Pesarattu dosa(3no.s) with kaara chutney(250ml), Omelette (1 nos) | B21: 99 | C21: 34.9 | D21: =0.3*B21 -> 29.7 | E21: =C21+D21 -> 64.6 | F21: =B21-E21 -> 34.4 | G21: =F21/B21*100 -> 34.747475 | H21: Star

Sheet Ingredient Costs
A1: Ingredients | B1: Local Vendor Cost | C1: Quick commerce cost | D1: Difference
A2: White rice (regular/parboiled) | B2: 55 | C2: 60 | D2: =((C2-B2)/B2) -> 0.090909091
A3: Basmati rice | B3: 115 | C3: 125 | D3: =((C3-B3)/B3) -> 0.086956522
A4: Seeraga samba rice | B4: 115 | C4: 130 | D4: =((C4-B4)/B4) -> 0.13043478
A5: Karuppu kavuni rice (black rice) | B5: 270 | C5: 300 | D5: =((C5-B5)/B5) -> 0.11111111
A6: Toor dal | B6: 180 | C6: 220 | D6: =((C6-B6)/B6) -> 0.22222222
A7: Moong dal | B7: 130 | C7: 146 | D7: =((C7-B7)/B7) -> 0.12307692
A8: Chana dal | B8: 105 | C8: 117 | D8: =((C8-B8)/B8) -> 0.11428571
A9: Urad dal | B9: 120 | C9: 136 | D9: =((C9-B9)/B9) -> 0.13333333
A10: Wheat flour (atta) | B10: 70 | C10: 77 | D10: =((C10-B10)/B10) -> 0.1
A11: Rice flour | B11: 70 | C11: 76 | D11: =((C11-B11)/B11) -> 0.085714286
A12: Gram flour (besan) | B12: 110 | C12: 112 | D12: =((C12-B12)/B12) -> 0.018181818
A13: Rava/Semolina | B13: 50 | C13: 50 | D13: =((C13-B13)/B13) -> 0
... A21: Cauliflower (gobi) (1 piece) | B21: 30 | C21: 50 | D21: =((C21-B21)/B21) -> 0.66666667
A22: Okra (vendakkai) (1000g) | B22: 40 | C22: =23*4 -> 92 | D22: =((C22-B22)/B22) -> 1.3
A23: Ridge gourd (peerkangai) (1000g) | B23: 40 | C23: 105 | D23: =((C23-B23)/B23) -> 1.625
A24: Bottle gourd (surakkai) (1 piece) | B24: 40 | C24: 50 | D24: =((C24-B24)/B24) -> 0.25
A25: Raw banana (vazhakkai) (1 piece) | B25: 10 | C25: 18 | D25: =((C25-B25)/B25) -> 0.8
A26: Mushroom (100 g) | B26: 40 | C26: 45 | D26: =((C26-B26)/B26) -> 0.125
A27: Spinach/greens (keerai) (100g) | B27: =(25/250)*100 -> 10 | C27: 15 | D27: =((C27-B27)/B27) -> 0.5
A28: Curry leaves (100g) | B28: 20 | C28: 20 | D28: =((C28-B28)/B28) -> 0
A29: Coriander leaves (100g) | B29: 10 | C29: 16 | D29: =((C29-B29)/B29) -> 0.6
A30: Mint leaves (100g) | B30: 10 | C30: 14 | D30: =((C30-B30)/B30) -> 0.4
A31: Veppam poo | B31: 40 | C31: 50 | D31: =((C31-B31)/B31) -> 0.25
A32: Pumpkin (500g) | B32: 30 | C32: 45 | D32: =((C32-B32)/B32) -> 0.5
A33: Brinjal/eggplant (1000g) | B33: 40 | C33: =22*2 -> 44 | D33: =((C33-B33)/B33) -> 0.1
A34: Cabbage (1 piece) | B34: 20 | C34: 30 | D34: =((C34-B34)/B34) -> 0.5
A35: Capsicum (1000g) | B35: 60 | C35: 96 | D35: =((C35-B35)/B35) -> 0.6
A36: Green chillies (1000g) | B36: 70 | C36: 140 | D36: =((C36-B36)/B36) -> 1
A37: Ginger (1000g) | B37: 110 | C37: =34*5 -> 170 | D37: =((C37-B37)/B37) -> 0.54545455
A38: Garlic (1000g) | B38: 150 | C38: =44*5 -> 220 | D38: =((C38-B38)/B38) -> 0.46666667
A39: Chicken (1000g) | B39: 200 | C39: 360 | D39: =((C39-B39)/B39) -> 0.8
A40: Eggs (1 piece) | B40: 6 | C40: 14 | D40: =((C40-B40)/B40) -> 1.3333333
A41: Mutton: With bones (1000g) | B41: 900 | C41: =(330/300)*1000 -> 1100 | D41: =((C41-B41)/B41) -> 0.22222222
A42: Ayala (mackerel) (1000g) | B42: 200 | C42: 500 | D42: =((C42-B42)/B42) -> 1.5
A43: Kavalai (1000g) | B43: 150 | C43: 200 | D43: =((C43-B43)/B43) -> 0.33333333
A44: Nethili (anchovies) karuvaadu (1000g) | B44: 200 | C44: 300 | D44: =((C44-B44)/B44) -> 0.5
A45: General fish varieties (1000g) | B45: 330 | C45: 450 | D45: =((C45-B45)/B45) -> 0.36363636
A46: Prawns (1000g) | B46: 280 | C46: 400 | D46: =((C46-B46)/B46) -> 0.42857143
A47: Crab (1000g) | B47: 300 | C47: 500 | D47: =((C47-B47)/B47) -> 0.66666667
...

Sheet Operational Events
A1: Date | B1: Event_Type | C1: Event_Name | D1: Impact | E1: Notes
A2: 05-04-2025 | B2: Weekend | C2: Saturday | D2: Low | E2: Weekend — moderate evening demand
A3: 06-04-2025 | B3: Weekend/Festival | C3: Sunday / Sri Rama Navami | D3: Medium | E3: Likely slight morning demand increase
A4: 10-04-2025 | B4: Holiday | C4: Mahaveer Jayanti | D4: Medium | E4: Public holiday — expect lower activity
A5: 11-04-2025 | B5: Festival | C5: Panguni Uthiram | D5: Medium | E5: Cultural festival — possible small demand bump
A6: 12-04-2025 | B6: Weekend | C6: Saturday | D6: Low | E6: Weekend — moderate evening demand
A7: 13-04-2025 | B7: Weekend | C7: Sunday | D7: Low | E7: Weekend — typical demand
A8: 14-04-2025 | B8: Festival | C8: Tamil New Year (Puthandu) | D8: High | E8: Major Tamil festival — expect 2–3× demand
A9: 18-04-2025 | B9: Holiday | C9: Good Friday | D9: Medium | E9: Public holiday — likely slower business activity
A10: 19-04-2025 | B10: Weekend | C10: Saturday | D10: Low | E10: Weekend — moderate evening demand
A11: 20-04-2025 | B11: Weekend | C11: Sunday | D11: Low | E11: Weekend — typical demand
A12: 23-04-2025 | B12: Festival | C12: Thirunavukarasu Guru Poojai | D12: Low/Medium | E12: Temple observance — modest demand impact
... A15: 30-04-2025 | B15: Festival | C15: Akshaya Tritiya | D15: Medium | E15: Auspicious day — possible increased orders
A16: 45778 | B16: Holiday | C16: May Day | D16: Medium | E16: Public holiday - medium activity expected

Sheet Availability matrix
A1: DishName | B1: Breakfast | C1: Lunch | D1: Snacks | E1: Dinner
A2: VadaKulambu | B2: =IF(COUNTIFS('Menu Details'!$B:$B,$A2,'Menu Details'!$C:$C,"Breakfast")>0,"✓","") | C2: =IF(COUNTIFS('Menu Details'!$B:$B,$A2,'Menu Details'!$C:$C,"Lunch")>0,"✓","") -> ✓ | D2: =IF(COUNTIFS('Menu Details'!$B:$B,$A2,'Menu Details'!$C:$C,"Snacks")>0,"✓","") | E2: =IF(COUNTIFS('Menu Details'!$B:$B,$A2,'Menu Details'!$C:$C,"Dinner")>0,"✓","")
A3: VathaKulambu | B3: =IF(COUNTIFS('Menu Details'!$B:$B,$A3,'Menu Details'!$C:$C,"Breakfast")>0,"✓","") | C3: =IF(COUNTIFS('Menu Details'!$B:$B,$A3,'Menu Details'!$C:$C,"Lunch")>0,"✓","") -> ✓ | D3: =IF(COUNTIFS('Menu Details'!$B:$B,$A3,'Menu Details'!$C:$C,"Snacks")>0,"✓","") | E3: =IF(COUNTIFS('Menu Details'!$B:$B,$A3,'Menu Details'!$C:$C,"Dinner")>0,"✓","")
A4: SemiyaKichadi | B4: =IF(COUNTIFS('Menu Details'!$B:$B,$A4,'Menu Details'!$C:$C,"Breakfast")>0,"✓","") -> ✓ | C4: =IF(COUNTIFS('Menu Details'!$B:$B,$A4,'Menu Details'!$C:$C,"Lunch")>0,"✓","") | D4: =IF(COUNTIFS('Menu Details'!$B:$B,$A4,'Menu Details'!$C:$C,"Snacks")>0,"✓","") -> ✓ | E4: =IF(COUNTIFS('Menu Details'!$B:$B,$A4,'Menu Details'!$C:$C,"Dinner")>0,"✓","") -> ✓
A5: Idlywithsambharandchutney | B5: =IF(COUNTIFS('Menu Details'!$B:$B,$A5,'Menu Details'!$C:$C,"Breakfast")>0,"✓","") -> ✓ | C5: =IF(COUNTIFS('Menu Details'!$B:$B,$A5,'Menu Details'!$C:$C,"Lunch")>0,"✓","") | D5: =IF(COUNTIFS('Menu Details'!$B:$B,$A5,'Menu Details'!$C:$C,"Snacks")>0,"✓","") | E5: =IF(COUNTIFS('Menu Details'!$B:$B,$A5,'Menu Details'!$C:$C,"Dinner")>0,"✓","") -> ✓
A6: VegBiryani | B6: =IF(COUNTIFS('Menu Details'!$B:$B,$A6,'Menu Details'!$C:$C,"Breakfast")>0,"✓","") | C6: =IF(COUNTIFS('Menu Details'!$B:$B,$A6,'Menu Details'!$C:$C,"Lunch")>0,"✓","") -> ✓ | D6: =IF(COUNTIFS('Menu Details'!$B:$B,$A6,'Menu Details'!$C:$C,"Snacks")>0,"✓","") | E6: =IF(COUNTIFS('Menu Details'!$B:$B,$A6,'Menu Details'!$C:$C,"Dinner")>0,"✓","") -> ✓
A7: PotatoThokku | B7: =IF(COUNTIFS('Menu Details'!$B:$B,$A7,'Menu Details'!$C:$C,"Breakfast")>0,"✓","") -> ✓ | C7: =IF(COUNTIFS('Menu Details'!$B:$B,$A7,'Menu Details'!$C:$C,"Lunch")>0,"✓","") -> ✓ | D7: =IF(COUNTIFS('Menu Details'!$B:$B,$A7,'Menu Details'!$C:$C,"Snacks")>0,"✓","") | E7: =IF(COUNTIFS('Menu Details'!$B:$B,$A7,'Menu Details'!$C:$C,"Dinner")>0,"✓","") -> ✓
A8: Eggfry | B8: =IF(COUNTIFS('Menu Details'!$B:$B,$A8,'Menu Details'!$C:$C,"Breakfast")>0,"✓","") | C8: =IF(COUNTIFS('Menu Details'!$B:$B,$A8,'Menu Details'!$C:$C,"Lunch")>0,"✓","") -> ✓ | D8: =IF(COUNTIFS('Menu Details'!$B:$B,$A8,'Menu Details'!$C:$C,"Snacks")>0,"✓","") | E8: =IF(COUNTIFS('Menu Details'!$B:$B,$A8,'Menu Details'!$C:$C,"Dinner")>0,"✓","") -> ✓
A9: Gobi65 | B9: =IF(COUNTIFS('Menu Details'!$B:$B,$A9,'Menu Details'!$C:$C,"Breakfast")>0,"✓","") | C9: =IF(COUNTIFS('Menu Details'!$B:$B,$A9,'Menu Details'!$C:$C,"Lunch")>0,"✓","") -> ✓ | D9: =IF(COUNTIFS('Menu Details'!$B:$B,$A9,'Menu Details'!$C:$C,"Snacks")>0,"✓","") | E9: =IF(COUNTIFS('Menu Details'!$B:$B,$A9,'Menu Details'!$C:$C,"Dinner")>0,"✓","") -> ✓
A10: Coconutricewithpotatothokku | B10: =IF(COUNTIFS('Menu Details'!$B:$B,$A10,'Menu Details'!$C:$C,"Breakfast")>0,"✓","") | C10: =IF(COUNTIFS('Menu Details'!$B:$B,$A10,'Menu Details'!$C:$C,"Lunch")>0,"✓","") -> ✓ | D10: =IF(COUNTIFS('Menu Details'!$B:$B,$A10,'Menu Details'!$C:$C,"Snacks")>0,"✓","") | E10: =IF(COUNTIFS('Menu Details'!$B:$B,$A10,'Menu Details'!$C:$C,"Dinner")>0,"✓","") -> ✓
A11: WhiteRice | B11: =IF(COUNTIFS('Menu Details'!$B:$B,$A11,'Menu Details'!$C:$C,"Breakfast")>0,"✓","") -> ✓ | C11: =IF(COUNTIFS('Menu Details'!$B:$B,$A11,'Menu Details'!$C:$C,"Lunch")>0,"✓","") -> ✓ | D11: =IF(COUNTIFS('Menu Details'!$B:$B,$A11,'Menu Details'!$C:$C,"Snacks")>0,"✓","") | E11: =IF(COUNTIFS('Menu Details'!$B:$B,$A11,'Menu Details'!$C:$C,"Dinner")>0,"✓","") -> ✓
A12: CurdRicewithPotatothokku | B12: =IF(COUNTIFS('Menu Details'!$B:$B,$A12,'Menu Details'!$C:$C,"Breakfast")>0,"✓","") -> ✓ | C12: =IF(COUNTIFS('Menu Details'!$B:$B,$A12,'Menu Details'!$C:$C,"Lunch")>0,"✓","") -> ✓ | D12: =IF(COUNTIFS('Menu Details'!$B:$B,$A12,'Menu Details'!$C:$C,"Snacks")>0,"✓","") | E12: =IF(COUNTIFS('Menu Details'!$B:$B,$A12,'Menu Details'!$C:$C,"Dinner")>0,"✓","") -> ✓
A13: Parupputhakkalikadayal | B13: =IF(COUNTIFS('Menu Details'!$B:$B,$A13,'Menu Details'!$C:$C,"Breakfast")>0,"✓","") -> ✓ | C13: =IF(COUNTIFS('Menu Details'!$B:$B,$A13,'Menu Details'!$C:$C,"Lunch")>0,"✓","") -> ✓ | D13: =IF(COUNTIFS('Menu Details'!$B:$B,$A13,'Menu Details'!$C:$C,"Snacks")>0,"✓","") | E13: =IF(COUNTIFS('Menu Details'!$B:$B,$A13,'Menu Details'!$C:$C,"Dinner")>0,"✓","") -> ✓
... A120: Pomegranatejuice | B120: =IF(COUNTIFS('Menu Details'!$B:$B,$A120,'Menu Details'!$C:$C,"Breakfast")>0,"✓","") -> ✓ | C120: =IF(COUNTIFS('Menu Details'!$B:$B,$A120,'Menu Details'!$C:$C,"Lunch")>0,"✓","") -> ✓ | D120: =IF(COUNTIFS('Menu Details'!$B:$B,$A120,'Menu Details'!$C:$C,"Snacks")>0,"✓","") -> ✓ | E120: =IF(COUNTIFS('Menu Details'!$B:$B,$A120,'Menu Details'!$C:$C,"Dinner")>0,"✓","")

Sheet Descriptive Analysis
A1: Daily Orders Statistics
A2: Metric | B2: Value | G2: DAILY SUMMARY | K2: WEEKLY STATISTICS TABLE
A3: Mean (Average Orders/Day) | B3: =AVERAGE(DailyOrders) -> 11.8125 | G3: PIVOT TABLE 1 | K3: PIVOT TABLE 2
A4: Median (Middle Value) | B4: =MEDIAN(DailyOrders) -> 13 | G4: Row Labels | H4: Count of ORDER ID | I4: Sum of ORDER VALUE | K4: Row Labels | L4: Count of ORDER ID | M4: % of Total | N4: Avg Revenue/Day
A5: Standard Deviation | B5: =_xlfn.STDEV.P(DailyOrders) -> 5.25062 | G5: 45748 | H5: 11 | I5: 1556 | K5: Monday | L5: 57 | M5: =(GETPIVOTDATA("Count of ORDER ID",$K$4,"DAY","Monday")/GETPIVOTDATA("Count of ORDER ID",$K$4))*100 -> 10.05291 | N5: =AVERAGEIF(Table5[DAY],"Monday",Table5[ORDER VALUE]) -> 189.89474
A6: Minimum | B6: =MIN(DailyOrders) -> 1 | G6: 45749 | H6: 11 | I6: 1660 | K6: Tuesday | L6: 92 | M6: =(GETPIVOTDATA("Count of ORDER ID",$K$4,"DAY","Tuesday")/GETPIVOTDATA("Count of ORDER ID",$K$4))*100 -> 16.22575 | N6: =AVERAGEIF(Table5[DAY],"Tuesday",Table5[ORDER VALUE]) -> 188.98901
A7: Maximum | B7: =MAX(DailyOrders) -> 21 | G7: 45750 | H7: 18 | I7: 3044 | K7: Wednesday | L7: 83 | M7: =(GETPIVOTDATA("Count of ORDER ID",$K$4,"DAY","Wednesday")/GETPIVOTDATA("Count of ORDER ID",$K$4))*100 -> 14.638448 | N7: =AVERAGEIF(Table5[DAY],"Wednesday",Table5[ORDER VALUE]) -> 205.93827
A8: Range (Max - Min) | B8: =MAX(DailyOrders)-MIN(DailyOrders) -> 20 | G8: 45751 | H8: 18 | I8: 3891 | K8: Thursday | L8: 100 | M8: =(GETPIVOTDATA("Count of ORDER ID",$K$4,"DAY","Thursday")/GETPIVOTDATA("Count of ORDER ID",$K$4))*100 -> 17.636684 | N8: =AVERAGEIF(Table5[DAY],"Thursday",Table5[ORDER VALUE]) -> 197.46
A9: Total Orders | B9: =SUM(DailyOrders) -> 567 | G9: 45752 | H9: 17 | I9: 3817 | K9: Friday | L9: 90 | M9: =(GETPIVOTDATA("Count of ORDER ID",$K$4,"DAY","Friday")/GETPIVOTDATA("Count of ORDER ID",$K$4))*100 -> 15.873016 | N9: =AVERAGEIF(Table5[DAY],"Friday",Table5[ORDER VALUE]) -> 194.72222
A10: Total Days | B10: =COUNT(DailyOrders) -> 48 | G10: 45753 | H10: 20 | I10: 5736 | K10: Saturday | L10: 73 | M10: =(GETPIVOTDATA("Count of ORDER ID",$K$4,"DAY","Saturday")/GETPIVOTDATA("Count of ORDER ID",$K$4))*100 -> 12.87478 | N10: =AVERAGEIF(Table5[DAY],"Saturday",Table5[ORDER VALUE]) -> 218.56164
A11: Coefficient of Variation | B11: =_xlfn.STDEV.P(DailyOrders)/AVERAGE(DailyOrders)*100 -> 44.449693 | G11: 45754 | H11: 16 | I11: 3772 | K11: Sunday | L11: 72 | M11: =(GETPIVOTDATA("Count of ORDER ID",$K$4,"DAY","Sunday")/GETPIVOTDATA("Count of ORDER ID",$K$4))*100 -> 12.698413 | N11: =AVERAGEIF(Table5[DAY],"Sunday",Table5[ORDER VALUE]) -> 278.56944
G12: 45755 | H12: 21 | I12: 5028 | K12: Grand Total | L12: 567 | M12: =SUM(M5:M11) -> 100 | N12: =SUM(N5:N11) -> 1474.1353
G13: 45756 | H13: 19 | I13: 3936
A14: Daily Revenue Statistics | G14: 45757 | H14: 15 | I14: 3179
A15: Metric | B15: Value | G15: 45758 | H15: 9 | I15: 1110 | K15: MEAL CATEGORY STATISTICS
A16: Mean (Average Revenue/Day) | B16: =AVERAGE(DailyRevenue) -> 2458.0417 | G16: 45759 | H16: 12 | I16: 2143 | K16: Row Labels | L16: NUMBER OF ORDERS | M16: REVENUE | N16: % of Revenue | O16: % of Share | P16: Avg Orders/Day
A17: Median | B17: =MEDIAN(DailyRevenue) -> 2516.5 | G17: 45760 | H17: 13 | I17: 3396 | K17: Breakfast | L17: 68 | M17: 8090 | N17: =GETPIVOTDATA("REVENUE",$K$16,"CATEGORY(BREAKFAST/LUNCH/SNACKS/DINNER)","Breakfast")/GETPIVOTDATA("REVENUE",$K$16)*100 -> 6.8567457 | O17: =GETPIVOTDATA("NUMBER OF ORDERS",$K$16,"CATEGORY(BREAKFAST/LUNCH/SNACKS/DINNER)","Breakfast")/GETPIVOTDATA("NUMBER OF ORDERS",$K$16)*100 -> 11.992945 | P17: =GETPIVOTDATA("ORDER ID",$K$16,"CATEGORY(BREAKFAST/LUNCH/SNACKS/DINNER)","Breakfast")/48 -> 1.4166667
A18: Standard Deviation | B18: =_xlfn.STDEV.P(DailyRevenue) -> 1303.6017 | G18: 45761 | H18: 8 | I18: 1184 | K18: Dinner | L18: 79 | M18: 8945 | N18: =GETPIVOTDATA("REVENUE",$K$16,"CATEGORY(BREAKFAST/LUNCH/SNACKS/DINNER)","Dinner")/GETPIVOTDATA("REVENUE",$K$16)*100 -> 7.581408 | O18: =GETPIVOTDATA("NUMBER OF ORDERS",$K$16,"CATEGORY(BREAKFAST/LUNCH/SNACKS/DINNER)","Dinner")/GETPIVOTDATA("NUMBER OF ORDERS",$K$16)*100 -> 13.932981 | P18: =GETPIVOTDATA("ORDER ID",$K$16,"CATEGORY(BREAKFAST/LUNCH/SNACKS/DINNER)","Dinner")/48 -> 1.6458333
A19: Minimum Daily Revenue | B19: =MIN(DailyRevenue) -> 129 | G19: 45762 | H19: 13 | I19: 1810 | K19: Lunch | L19: 420 | M19: 100951 | N19: =GETPIVOTDATA("REVENUE",$K$16,"CATEGORY(BREAKFAST/LUNCH/SNACKS/DINNER)","Lunch")/GETPIVOTDATA("REVENUE",$K$16)*100 -> 85.561846 | O19: =GETPIVOTDATA("NUMBER OF ORDERS",$K$16,"CATEGORY(BREAKFAST/LUNCH/SNACKS/DINNER)","Lunch")/GETPIVOTDATA("NUMBER OF ORDERS",$K$16)*100 -> 74.074074 | P19: =GETPIVOTDATA("ORDER ID",$K$16,"CATEGORY(BREAKFAST/LUNCH/SNACKS/DINNER)","Lunch")/48 -> 8.75
A20: Maximum Daily Revenue | B20: =MAX(DailyRevenue) -> 5736 | G20: 45763 | H20: 15 | I20: 2786 | K20: Grand Total | L20: 567 | M20: 117986 | N20: =SUM(N17:N19) -> 100 | O20: =SUM(O17:O19) -> 100 | P20: =SUM(P17:P19) -> 11.8125
A21: Range | B21: =MAX(DailyRevenue)-MIN(DailyRevenue) -> 5607 | G21: 45764 | H21: 13 | I21: 2255
A22: Total Revenue | B22: =SUM(DailyRevenue) -> 117986 | G22: 45765 | H22: 16 | I22: 3280
A23: Total Days | B23: =COUNT(DailyOrders) -> 48 | G23: 45766 | H23: 16 | I23: 3595 | K23: ORDER TYPE STATISTICS
A24: Coefficient of Variation | B24: =_xlfn.STDEV.P(DailyRevenue)/AVERAGE(DailyRevenue)*100 -> 53.034158 | G24: 45767 | H24: 14 | I24: 3814 | K24: Row Labels | L24: NUMBER OF ORDERS | M24: REVENUE | N24: % of Orders | O24: Avg Order/ Day | P24: % of Revenue
G25: 45768 | H25: 5 | I25: 503 | K25: REGULAR | L25: 269 | M25: 81216 | N25: =GETPIVOTDATA("NUMBER OF ORDERS",$K$24,"TYPE(SUBSCRIPTION/REGULAR)","REGULAR")/GETPIVOTDATA("NUMBER OF ORDERS",$K$24)*100 -> 47.442681 | O25: =GETPIVOTDATA("NUMBER OF ORDERS",$K$24,"TYPE(SUBSCRIPTION/REGULAR)","REGULAR")/48 -> 5.6041667 | P25: =GETPIVOTDATA("REVENUE",$K$24,"TYPE(SUBSCRIPTION/REGULAR)","REGULAR")/GETPIVOTDATA("REVENUE",$K$24)*100 -> 68.835286
G26: 45769 | H26: 10 | I26: 1529 | K26: SUBSCRIPTION | L26: 298 | M26: 36770 | N26: =GETPIVOTDATA("NUMBER OF ORDERS",$K$24,"TYPE(SUBSCRIPTION/REGULAR)","SUBSCRIPTION")/GETPIVOTDATA("NUMBER OF ORDERS",$K$24)*100 -> 52.557319 | O26: =GETPIVOTDATA("NUMBER OF ORDERS",$K$24,"TYPE(SUBSCRIPTION/REGULAR)","SUBSCRIPTION")/48 -> 6.2083333 | P26: =GETPIVOTDATA("REVENUE",$K$24,"TYPE(SUBSCRIPTION/REGULAR)","SUBSCRIPTION")/GETPIVOTDATA("REVENUE",$K$24)*100 -> 31.164714
G27: 45770 | H27: 12 | I27: 2256 | K27: Grand Total | L27: 567 | M27: 117986 | N27: =SUM(N25:N26) -> 100 | O27: =SUM(O25:O26) -> 11.8125 | P27: =SUM(P25:P26) -> 100
G28: 45771 | H28: 13 | I28: 2442
G29: 45772 | H29: 7 | I29: 874
G30: 45773 | H30: 14 | I30: 3043 | K30: VEG VS NON-VEG STATISTICS
G31: 45774 | H31: 11 | I31: 2924 | K31: Row Labels | L31: No.Of Items
G32: 45775 | H32: 13 | I32: 2690 | K32: Non-veg | L32: 386
G33: 45776 | H33: 13 | I33: 2390 | K33: Veg | L33: 494
G34: 45778 | H34: 15 | I34: 3826 | K34: Grand Total | L34: 880
G35: 45779 | H35: 15 | I35: 3048
G36: 45780 | H36: 2 | I36: 278
G37: 45781 | H37: 1 | I37: 280
G38: 45782 | H38: 2 | I38: 289
G39: 45783 | H39: 6 | I39: 1984
G40: 45784 | H40: 8 | I40: 2179
...
